#usda 1.0
(
    customLayerData = {
        string creator = "URDF USD Converter v0.1.0"
    }
    defaultPrim = "inspire_hand_right"
    doc = """Generated from Composed Stage of root layer /tmp/tmpumakolso/inspire_hand_right.usdc


Generated from Composed Stage of root layer /home/hongyi/scalevideomanip/dex-retargeting/example/position_retargeting/inspire/inspire_hand_right/usdex/inspire_hand_right.usdc


Generated from Composed Stage of root layer /home/hongyi/scalevideomanip/dex-retargeting/example/position_retargeting/inspire/inspire_hand_right/temp/inspire_hand_right.usd


Generated from Composed Stage of root layer /home/hongyi/scalevideomanip/dex-retargeting/example/position_retargeting/inspire/inspire_hand_right/inspire_hand_right/payloads/base.usd
"""
    kilogramsPerUnit = 1
    metersPerUnit = 1
    upAxis = "Z"
)

over "inspire_hand_right"
{
    over "Geometry"
    {
        over "base" (
            prepend apiSchemas = ["PhysicsRigidBodyAPI", "PhysicsArticulationRootAPI", "NewtonArticulationRootAPI", "PhysicsMassAPI"]
        )
        {
            bool newton:selfCollisionEnabled = 0
            point3f physics:centerOfMass = (-0.06604701, -0.0025259757, -0.001960034)
            float3 physics:diagonalInertia = (0.00007619508, 0.0000841186, 0.00012299132)
            float physics:mass = 0.14143
            quatf physics:principalAxes = (0.41688898, 0.46258992, 0.5514306, 0.5551022)

            over "thumb_proximal_base" (
                prepend apiSchemas = ["PhysicsRigidBodyAPI", "PhysicsMassAPI"]
            )
            {
                point3f physics:centerOfMass = (-0.0048064, 0.0009382, -0.00757)
                float3 physics:diagonalInertia = (4.9419366e-8, 6.873204e-8, 8.660259e-8)
                float physics:mass = 0.0018869
                quatf physics:principalAxes = (-0.6526865, 0.71025336, -0.075654514, -0.2526202)

                over "thumb_proximal" (
                    prepend apiSchemas = ["PhysicsRigidBodyAPI", "PhysicsMassAPI"]
                )
                {
                    point3f physics:centerOfMass = (0.021932, 0.012785, -0.0080386)
                    float3 physics:diagonalInertia = (8.64566e-7, 0.0000024393287, 0.0000027860053)
                    float physics:mass = 0.0066075
                    quatf physics:principalAxes = (0.9336983, -0.0018248791, -0.00069463777, -0.3580555)

                    over "thumb_intermediate" (
                        prepend apiSchemas = ["PhysicsRigidBodyAPI", "PhysicsMassAPI"]
                    )
                    {
                        point3f physics:centerOfMass = (0.0095544, -0.0016282, -0.0071997)
                        float3 physics:diagonalInertia = (2.4566123e-7, 4.4808877e-7, 4.6531e-7)
                        float physics:mass = 0.0037847
                        quatf physics:principalAxes = (-0.00011290622, 0.90051436, 0.43482625, 0.00005981473)

                        over "thumb_distal" (
                            prepend apiSchemas = ["PhysicsRigidBodyAPI", "PhysicsMassAPI"]
                        )
                        {
                            point3f physics:centerOfMass = (0.0092888, 0.0049529, -0.0060033)
                            float3 physics:diagonalInertia = (8.159299e-8, 1.952467e-7, 2.0026032e-7)
                            float physics:mass = 0.0033441
                            quatf physics:principalAxes = (0.9273728, -0.0024661468, -0.00030418276, -0.3741303)
                        }
                    }
                }
            }

            over "index_proximal" (
                prepend apiSchemas = ["PhysicsRigidBodyAPI", "PhysicsMassAPI"]
            )
            {
                point3f physics:centerOfMass = (0.0012259, 0.011942, -0.0060001)
                float3 physics:diagonalInertia = (2.1090872e-7, 6.628713e-7, 6.9398e-7)
                float physics:mass = 0.0042403
                quatf physics:principalAxes = (0.00002705187, 0.71934855, 0.69464934, -0.00001890708)

                over "index_intermediate" (
                    prepend apiSchemas = ["PhysicsRigidBodyAPI", "PhysicsMassAPI"]
                )
                {
                    point3f physics:centerOfMass = (0.0019697, 0.019589, -0.005)
                    float3 physics:diagonalInertia = (8.472122e-8, 7.724648e-7, 7.8179e-7)
                    float physics:mass = 0.0045683
                    quatf physics:principalAxes = (-0.000009285805, 0.6601167, 0.75116307, 0.000009442229)
                }
            }

            over "middle_proximal" (
                prepend apiSchemas = ["PhysicsRigidBodyAPI", "PhysicsMassAPI"]
            )
            {
                point3f physics:centerOfMass = (0.001297, 0.011934, -0.0060001)
                float3 physics:diagonalInertia = (2.1091465e-7, 6.628653e-7, 6.9397e-7)
                float physics:mass = 0.0042403
                quatf physics:principalAxes = (0.000028758006, 0.7214158, 0.69250214, -0.000018133493)

                over "middle_intermediate" (
                    prepend apiSchemas = ["PhysicsRigidBodyAPI", "PhysicsMassAPI"]
                )
                {
                    point3f physics:centerOfMass = (0.001921, 0.020796, -0.005)
                    float3 physics:diagonalInertia = (9.140141e-8, 9.732786e-7, 9.8384e-7)
                    float physics:mass = 0.0050396
                    quatf physics:principalAxes = (-0.00005518809, 0.6592899, 0.7518888, 0.000057678717)
                }
            }

            over "ring_proximal" (
                prepend apiSchemas = ["PhysicsRigidBodyAPI", "PhysicsMassAPI"]
            )
            {
                point3f physics:centerOfMass = (0.001297, 0.011934, -0.0060002)
                float3 physics:diagonalInertia = (2.1091465e-7, 6.628653e-7, 6.9397e-7)
                float physics:mass = 0.0042403
                quatf physics:principalAxes = (0.000026212076, 0.7214158, 0.69250214, -0.000015668043)

                over "ring_intermediate" (
                    prepend apiSchemas = ["PhysicsRigidBodyAPI", "PhysicsMassAPI"]
                )
                {
                    point3f physics:centerOfMass = (0.0021753, 0.019567, -0.005)
                    float3 physics:diagonalInertia = (8.4721975e-8, 7.72448e-7, 7.8177e-7)
                    float physics:mass = 0.0045683
                    quatf physics:principalAxes = (-0.000019659374, 0.66405016, 0.747688, 0.000021428197)
                }
            }

            over "pinky_proximal" (
                prepend apiSchemas = ["PhysicsRigidBodyAPI", "PhysicsMassAPI"]
            )
            {
                point3f physics:centerOfMass = (0.001297, 0.011934, -0.0060001)
                float3 physics:diagonalInertia = (2.1091465e-7, 6.628653e-7, 6.9397e-7)
                float physics:mass = 0.0042403
                quatf physics:principalAxes = (0.000027793114, 0.7214158, 0.69250214, -0.000016838727)

                over "pinky_intermediate" (
                    prepend apiSchemas = ["PhysicsRigidBodyAPI", "PhysicsMassAPI"]
                )
                {
                    point3f physics:centerOfMass = (0.0024748, 0.016203, -0.0050031)
                    float3 physics:diagonalInertia = (6.565379e-8, 4.4372283e-7, 4.486704e-7)
                    float physics:mass = 0.0035996
                    quatf physics:principalAxes = (0.0028730568, 0.6669935, 0.74505067, -0.003315285)
                }
            }

            over "cylinder" (
                prepend apiSchemas = ["NewtonCollisionAPI"]
            )
            {
            }

            over "box" (
                prepend apiSchemas = ["NewtonCollisionAPI"]
            )
            {
            }

            over "box_1" (
                prepend apiSchemas = ["NewtonCollisionAPI"]
            )
            {
            }

            over "box_2" (
                prepend apiSchemas = ["NewtonCollisionAPI"]
            )
            {
            }

            over "box_3" (
                prepend apiSchemas = ["NewtonCollisionAPI"]
            )
            {
            }

            over "box_4" (
                prepend apiSchemas = ["NewtonCollisionAPI"]
            )
            {
            }

            over "box_5" (
                prepend apiSchemas = ["NewtonCollisionAPI"]
            )
            {
            }

            over "box_6" (
                prepend apiSchemas = ["NewtonCollisionAPI"]
            )
            {
            }
        }
    }

    over "Physics"
    {
        def PhysicsRevoluteJoint "thumb_proximal_yaw_joint" (
            prepend apiSchemas = ["PhysicsDriveAPI:angular", "PhysicsJointStateAPI:angular"]
        )
        {
            uniform token physics:axis = "Z"
            custom rel physics:body0
            prepend rel physics:body0 = </inspire_hand_right/Geometry/base>
            custom rel physics:body1
            prepend rel physics:body1 = </inspire_hand_right/Geometry/base/thumb_proximal_base>
            point3f physics:localPos0 = (-0.06910006, -0.016961642, 0.020448428)
            point3f physics:localPos1 = (0, 0, 0)
            quatf physics:localRot0 = (-0.70710677, -0.00003405652, -0.70710677, -0.000028862403)
            quatf physics:localRot1 = (0, -1, 0, 0)
            float physics:lowerLimit = 0
            float physics:upperLimit = 74.94288
            custom float urdf:limit:effort = 1
            custom float urdf:limit:velocity = 0.5
        }

        def PhysicsRevoluteJoint "thumb_proximal_pitch_joint" (
            prepend apiSchemas = ["PhysicsDriveAPI:angular", "PhysicsJointStateAPI:angular"]
        )
        {
            uniform token physics:axis = "Z"
            custom rel physics:body0
            prepend rel physics:body0 = </inspire_hand_right/Geometry/base/thumb_proximal_base>
            custom rel physics:body1
            prepend rel physics:body1 = </inspire_hand_right/Geometry/base/thumb_proximal_base/thumb_proximal>
            point3f physics:localPos0 = (-0.0088099, 0.010892, -0.00925)
            point3f physics:localPos1 = (0, 0, 0)
            quatf physics:localRot0 = (0.0996843, 0.09968466, 0.7000463, 0.70004374)
            quatf physics:localRot1 = (1, 0, 0, 0)
            float physics:lowerLimit = 0
            float physics:upperLimit = 34.37747
            custom float urdf:limit:effort = 1
            custom float urdf:limit:velocity = 0.5
        }

        def PhysicsRevoluteJoint "thumb_intermediate_joint" (
            prepend apiSchemas = ["NewtonMimicAPI", "PhysicsDriveAPI:angular", "PhysicsJointStateAPI:angular"]
        )
        {
            float newton:mimicCoef1 = 1.334
            rel newton:mimicJoint = </inspire_hand_right/Physics/thumb_proximal_pitch_joint>
            uniform token physics:axis = "Z"
            custom rel physics:body0
            prepend rel physics:body0 = </inspire_hand_right/Geometry/base/thumb_proximal_base/thumb_proximal>
            custom rel physics:body1
            prepend rel physics:body1 = </inspire_hand_right/Geometry/base/thumb_proximal_base/thumb_proximal/thumb_intermediate>
            point3f physics:localPos0 = (0.04407, 0.034553, -0.0008)
            point3f physics:localPos1 = (0, 0, 0)
            quatf physics:localRot0 = (1, 0, 0, 0)
            quatf physics:localRot1 = (1, 0, 0, 0)
            float physics:lowerLimit = 0
            float physics:upperLimit = 45.836624
            custom float urdf:limit:effort = 1
            custom float urdf:limit:velocity = 0.5
        }

        def PhysicsRevoluteJoint "thumb_distal_joint" (
            prepend apiSchemas = ["NewtonMimicAPI", "PhysicsDriveAPI:angular", "PhysicsJointStateAPI:angular"]
        )
        {
            float newton:mimicCoef1 = 0.667
            rel newton:mimicJoint = </inspire_hand_right/Physics/thumb_proximal_pitch_joint>
            uniform token physics:axis = "Z"
            custom rel physics:body0
            prepend rel physics:body0 = </inspire_hand_right/Geometry/base/thumb_proximal_base/thumb_proximal/thumb_intermediate>
            custom rel physics:body1
            prepend rel physics:body1 = </inspire_hand_right/Geometry/base/thumb_proximal_base/thumb_proximal/thumb_intermediate/thumb_distal>
            point3f physics:localPos0 = (0.020248, 0.010156, -0.0012)
            point3f physics:localPos1 = (0, 0, 0)
            quatf physics:localRot0 = (1, 0, 0, 0)
            quatf physics:localRot1 = (1, 0, 0, 0)
            float physics:lowerLimit = 0
            float physics:upperLimit = 22.918312
            custom float urdf:limit:effort = 1
            custom float urdf:limit:velocity = 0.5
        }

        def PhysicsRevoluteJoint "index_proximal_joint" (
            prepend apiSchemas = ["PhysicsDriveAPI:angular", "PhysicsJointStateAPI:angular"]
        )
        {
            uniform token physics:axis = "Z"
            custom rel physics:body0
            prepend rel physics:body0 = </inspire_hand_right/Geometry/base>
            custom rel physics:body1
            prepend rel physics:body1 = </inspire_hand_right/Geometry/base/index_proximal>
            point3f physics:localPos0 = (-0.13653, 0.00028284176, 0.032268025)
            point3f physics:localPos1 = (0, 0, 0)
            quatf physics:localRot0 = (0.7069999, 0.012368565, 0.012303014, 0.70699847)
            quatf physics:localRot1 = (1, 0, 0, 0)
            float physics:lowerLimit = 0
            float physics:upperLimit = 84.22479
            custom float urdf:limit:effort = 1
            custom float urdf:limit:velocity = 0.5
        }

        def PhysicsRevoluteJoint "index_intermediate_joint" (
            prepend apiSchemas = ["NewtonMimicAPI", "PhysicsDriveAPI:angular", "PhysicsJointStateAPI:angular"]
        )
        {
            float newton:mimicCoef0 = -0.04545
            float newton:mimicCoef1 = 1.06399
            rel newton:mimicJoint = </inspire_hand_right/Physics/index_proximal_joint>
            uniform token physics:axis = "Z"
            custom rel physics:body0
            prepend rel physics:body0 = </inspire_hand_right/Geometry/base/index_proximal>
            custom rel physics:body1
            prepend rel physics:body1 = </inspire_hand_right/Geometry/base/index_proximal/index_intermediate>
            point3f physics:localPos0 = (-0.0026138, 0.032026, -0.001)
            point3f physics:localPos1 = (0, 0, 0)
            quatf physics:localRot0 = (1, 0, 0, 0)
            quatf physics:localRot1 = (1, 0, 0, 0)
            float physics:lowerLimit = -2.604093
            float physics:upperLimit = 89.38142
            custom float urdf:limit:effort = 1
            custom float urdf:limit:velocity = 0.5
        }

        def PhysicsRevoluteJoint "middle_proximal_joint" (
            prepend apiSchemas = ["PhysicsDriveAPI:angular", "PhysicsJointStateAPI:angular"]
        )
        {
            uniform token physics:axis = "Z"
            custom rel physics:body0
            prepend rel physics:body0 = </inspire_hand_right/Geometry/base>
            custom rel physics:body1
            prepend rel physics:body1 = </inspire_hand_right/Geometry/base/middle_proximal>
            point3f physics:localPos0 = (-0.1371, 0.00028463374, 0.012950026)
            point3f physics:localPos1 = (0, 0, 0)
            quatf physics:localRot0 = (0.7071081, 0.00003016058, -0.000035355395, 0.70710546)
            quatf physics:localRot1 = (1, 0, 0, 0)
            float physics:lowerLimit = 0
            float physics:upperLimit = 84.22479
            custom float urdf:limit:effort = 1
            custom float urdf:limit:velocity = 0.5
        }

        def PhysicsRevoluteJoint "middle_intermediate_joint" (
            prepend apiSchemas = ["NewtonMimicAPI", "PhysicsDriveAPI:angular", "PhysicsJointStateAPI:angular"]
        )
        {
            float newton:mimicCoef0 = -0.04545
            float newton:mimicCoef1 = 1.06399
            rel newton:mimicJoint = </inspire_hand_right/Physics/middle_proximal_joint>
            uniform token physics:axis = "Z"
            custom rel physics:body0
            prepend rel physics:body0 = </inspire_hand_right/Geometry/base/middle_proximal>
            custom rel physics:body1
            prepend rel physics:body1 = </inspire_hand_right/Geometry/base/middle_proximal/middle_intermediate>
            point3f physics:localPos0 = (-0.0024229, 0.032041, -0.001)
            point3f physics:localPos1 = (0, 0, 0)
            quatf physics:localRot0 = (1, 0, 0, 0)
            quatf physics:localRot1 = (1, 0, 0, 0)
            float physics:lowerLimit = -2.604093
            float physics:upperLimit = 89.38142
            custom float urdf:limit:effort = 1
            custom float urdf:limit:velocity = 0.5
        }

        def PhysicsRevoluteJoint "ring_proximal_joint" (
            prepend apiSchemas = ["PhysicsDriveAPI:angular", "PhysicsJointStateAPI:angular"]
        )
        {
            uniform token physics:axis = "Z"
            custom rel physics:body0
            prepend rel physics:body0 = </inspire_hand_right/Geometry/base>
            custom rel physics:body1
            prepend rel physics:body1 = </inspire_hand_right/Geometry/base/ring_proximal>
            point3f physics:localPos0 = (-0.13690999, 0.00028641542, -0.0062871734)
            point3f physics:localPos1 = (0, 0, 0)
            quatf physics:localRot0 = (0.7068663, -0.018488768, -0.018554194, 0.70686203)
            quatf physics:localRot1 = (1, 0, 0, 0)
            float physics:lowerLimit = 0
            float physics:upperLimit = 84.22479
            custom float urdf:limit:effort = 1
            custom float urdf:limit:velocity = 0.5
        }

        def PhysicsRevoluteJoint "ring_intermediate_joint" (
            prepend apiSchemas = ["NewtonMimicAPI", "PhysicsDriveAPI:angular", "PhysicsJointStateAPI:angular"]
        )
        {
            float newton:mimicCoef0 = -0.04545
            float newton:mimicCoef1 = 1.06399
            rel newton:mimicJoint = </inspire_hand_right/Physics/ring_proximal_joint>
            uniform token physics:axis = "Z"
            custom rel physics:body0
            prepend rel physics:body0 = </inspire_hand_right/Geometry/base/ring_proximal>
            custom rel physics:body1
            prepend rel physics:body1 = </inspire_hand_right/Geometry/base/ring_proximal/ring_intermediate>
            point3f physics:localPos0 = (-0.0024229, 0.032041, -0.001)
            point3f physics:localPos1 = (0, 0, 0)
            quatf physics:localRot0 = (1, 0, 0, 0)
            quatf physics:localRot1 = (1, 0, 0, 0)
            float physics:lowerLimit = -2.604093
            float physics:upperLimit = 89.38142
            custom float urdf:limit:effort = 1
            custom float urdf:limit:velocity = 0.5
        }

        def PhysicsRevoluteJoint "pinky_proximal_joint" (
            prepend apiSchemas = ["PhysicsDriveAPI:angular", "PhysicsJointStateAPI:angular"]
        )
        {
            uniform token physics:axis = "Z"
            custom rel physics:body0
            prepend rel physics:body0 = </inspire_hand_right/Geometry/base>
            custom rel physics:body1
            prepend rel physics:body1 = </inspire_hand_right/Geometry/base/pinky_proximal>
            point3f physics:localPos0 = (-0.13571, 0.00028819006, -0.025487974)
            point3f physics:localPos1 = (0, 0, 0)
            quatf physics:localRot0 = (0.70614123, -0.036964897, -0.037030187, 0.7061352)
            quatf physics:localRot1 = (1, 0, 0, 0)
            float physics:lowerLimit = 0
            float physics:upperLimit = 84.22479
            custom float urdf:limit:effort = 1
            custom float urdf:limit:velocity = 0.5
        }

        def PhysicsRevoluteJoint "pinky_intermediate_joint" (
            prepend apiSchemas = ["NewtonMimicAPI", "PhysicsDriveAPI:angular", "PhysicsJointStateAPI:angular"]
        )
        {
            float newton:mimicCoef0 = -0.04545
            float newton:mimicCoef1 = 1.06399
            rel newton:mimicJoint = </inspire_hand_right/Physics/pinky_proximal_joint>
            uniform token physics:axis = "Z"
            custom rel physics:body0
            prepend rel physics:body0 = </inspire_hand_right/Geometry/base/pinky_proximal>
            custom rel physics:body1
            prepend rel physics:body1 = </inspire_hand_right/Geometry/base/pinky_proximal/pinky_intermediate>
            point3f physics:localPos0 = (-0.0024229, 0.032041, -0.001)
            point3f physics:localPos1 = (0, 0, 0)
            quatf physics:localRot0 = (1, 0, 0, 0)
            quatf physics:localRot1 = (1, 0, 0, 0)
            float physics:lowerLimit = -2.604093
            float physics:upperLimit = 89.38142
            custom float urdf:limit:effort = 1
            custom float urdf:limit:velocity = 0.5
        }

        def PhysicsFixedJoint "root_joint"
        {
            custom rel physics:body0
            prepend rel physics:body0 = </inspire_hand_right>
            custom rel physics:body1
            prepend rel physics:body1 = </inspire_hand_right/Geometry/base>
            point3f physics:localPos0 = (0, 0, 0)
            point3f physics:localPos1 = (0, 0, 0)
            quatf physics:localRot0 = (1, 0, 0, 0)
            quatf physics:localRot1 = (1, 0, 0, 0)
        }
    }

    def PhysicsFixedJoint "fix_base_joint"
    {
        custom rel physics:body1
        prepend rel physics:body1 = </inspire_hand_right/Geometry/base>
    }
}

